[2025-03-28T18:00:49.511+0000] {local_task_job_runner.py:123} INFO - ::group::Pre task execution logs
[2025-03-28T18:00:49.687+0000] {taskinstance.py:2614} INFO - Dependencies all met for dep_context=non-requeueable deps ti=<TaskInstance: Etl_pipeline_order_management.store_data manual__2025-03-28T17:55:39.122963+00:00 [queued]>
[2025-03-28T18:00:49.699+0000] {taskinstance.py:2614} INFO - Dependencies all met for dep_context=requeueable deps ti=<TaskInstance: Etl_pipeline_order_management.store_data manual__2025-03-28T17:55:39.122963+00:00 [queued]>
[2025-03-28T18:00:49.699+0000] {taskinstance.py:2867} INFO - Starting attempt 2 of 2
[2025-03-28T18:00:49.714+0000] {taskinstance.py:2890} INFO - Executing <Task(PythonOperator): store_data> on 2025-03-28 17:55:39.122963+00:00
[2025-03-28T18:00:49.723+0000] {warnings.py:112} WARNING - /home/***/.local/lib/python3.12/site-packages/***/task/task_runner/standard_task_runner.py:70: DeprecationWarning: This process (pid=1744) is multi-threaded, use of fork() may lead to deadlocks in the child.
  pid = os.fork()

[2025-03-28T18:00:49.725+0000] {standard_task_runner.py:72} INFO - Started process 1746 to run task
[2025-03-28T18:00:49.725+0000] {standard_task_runner.py:104} INFO - Running: ['***', 'tasks', 'run', 'Etl_pipeline_order_management', 'store_data', 'manual__2025-03-28T17:55:39.122963+00:00', '--job-id', '81', '--raw', '--subdir', 'DAGS_FOLDER/Gestioncommands.py', '--cfg-path', '/tmp/tmpyx11ds4h']
[2025-03-28T18:00:49.727+0000] {standard_task_runner.py:105} INFO - Job 81: Subtask store_data
[2025-03-28T18:00:49.774+0000] {task_command.py:467} INFO - Running <TaskInstance: Etl_pipeline_order_management.store_data manual__2025-03-28T17:55:39.122963+00:00 [running]> on host 499696d11f67
[2025-03-28T18:00:49.862+0000] {taskinstance.py:3134} INFO - Exporting env vars: AIRFLOW_CTX_DAG_OWNER='***' AIRFLOW_CTX_DAG_ID='Etl_pipeline_order_management' AIRFLOW_CTX_TASK_ID='store_data' AIRFLOW_CTX_EXECUTION_DATE='2025-03-28T17:55:39.122963+00:00' AIRFLOW_CTX_TRY_NUMBER='2' AIRFLOW_CTX_DAG_RUN_ID='manual__2025-03-28T17:55:39.122963+00:00'
[2025-03-28T18:00:49.864+0000] {logging_mixin.py:190} INFO - Task instance is in running state
[2025-03-28T18:00:49.865+0000] {logging_mixin.py:190} INFO -  Previous state of the Task instance: queued
[2025-03-28T18:00:49.865+0000] {logging_mixin.py:190} INFO - Current task name:store_data state:running start_date:2025-03-28 18:00:49.687782+00:00
[2025-03-28T18:00:49.866+0000] {logging_mixin.py:190} INFO - Dag name:Etl_pipeline_order_management and current dag run status:running
[2025-03-28T18:00:49.866+0000] {taskinstance.py:732} INFO - ::endgroup::
[2025-03-28T18:00:49.867+0000] {Gestioncommands.py:44} INFO - Retrieving CSV data from XCom...
[2025-03-28T18:00:49.902+0000] {Gestioncommands.py:105} INFO - Inserting data into DuckDB tables...
[2025-03-28T18:00:49.938+0000] {Gestioncommands.py:140} ERROR - Error during storing data: Constraint Error: PRIMARY KEY or UNIQUE constraint violation: duplicate key "632"
[2025-03-28T18:00:49.940+0000] {taskinstance.py:3313} ERROR - Task failed with exception
Traceback (most recent call last):
  File "/home/airflow/.local/lib/python3.12/site-packages/airflow/models/taskinstance.py", line 768, in _execute_task
    result = _execute_callable(context=context, **execute_callable_kwargs)
             ^^^^^^^^^^^^^^^^^^^^^^^^^^^^^^^^^^^^^^^^^^^^^^^^^^^^^^^^^^^^^
  File "/home/airflow/.local/lib/python3.12/site-packages/airflow/models/taskinstance.py", line 734, in _execute_callable
    return ExecutionCallableRunner(
           ^^^^^^^^^^^^^^^^^^^^^^^^
  File "/home/airflow/.local/lib/python3.12/site-packages/airflow/utils/operator_helpers.py", line 252, in run
    return self.func(*args, **kwargs)
           ^^^^^^^^^^^^^^^^^^^^^^^^^^
  File "/home/airflow/.local/lib/python3.12/site-packages/airflow/models/baseoperator.py", line 424, in wrapper
    return func(self, *args, **kwargs)
           ^^^^^^^^^^^^^^^^^^^^^^^^^^^
  File "/home/airflow/.local/lib/python3.12/site-packages/airflow/operators/python.py", line 238, in execute
    return_value = self.execute_callable()
                   ^^^^^^^^^^^^^^^^^^^^^^^
  File "/home/airflow/.local/lib/python3.12/site-packages/airflow/operators/python.py", line 256, in execute_callable
    return runner.run(*self.op_args, **self.op_kwargs)
           ^^^^^^^^^^^^^^^^^^^^^^^^^^^^^^^^^^^^^^^^^^^
  File "/home/airflow/.local/lib/python3.12/site-packages/airflow/utils/operator_helpers.py", line 252, in run
    return self.func(*args, **kwargs)
           ^^^^^^^^^^^^^^^^^^^^^^^^^^
  File "/opt/airflow/dags/Gestioncommands.py", line 54, in store_data
    with duckdb.connect(DB_PATH) as conn:
         ^^^^^^^^^^^^^^^^^^^^^^^
  File "/opt/airflow/dags/Gestioncommands.py", line 111, in store_data
    conn.execute("INSERT INTO raw.clients SELECT * FROM clients_df")
duckdb.duckdb.ConstraintException: Constraint Error: PRIMARY KEY or UNIQUE constraint violation: duplicate key "632"
[2025-03-28T18:00:49.956+0000] {logging_mixin.py:190} INFO - Task instance in failure state
[2025-03-28T18:00:49.957+0000] {logging_mixin.py:190} INFO - Task start:2025-03-28 18:00:49.687782+00:00 end:2025-03-28 18:00:49.955875+00:00 duration:0.268093
[2025-03-28T18:00:49.957+0000] {logging_mixin.py:190} INFO - Task:<Task(PythonOperator): store_data> dag:<DAG: Etl_pipeline_order_management> dagrun:<DagRun Etl_pipeline_order_management @ 2025-03-28 17:55:39.122963+00:00: manual__2025-03-28T17:55:39.122963+00:00, state:running, queued_at: 2025-03-28 17:55:39.145356+00:00. externally triggered: True>
[2025-03-28T18:00:49.958+0000] {logging_mixin.py:190} INFO - Failure caused by Constraint Error: PRIMARY KEY or UNIQUE constraint violation: duplicate key "632"
[2025-03-28T18:00:49.959+0000] {taskinstance.py:1226} INFO - Marking task as FAILED. dag_id=Etl_pipeline_order_management, task_id=store_data, run_id=manual__2025-03-28T17:55:39.122963+00:00, execution_date=20250328T175539, start_date=20250328T180049, end_date=20250328T180049
[2025-03-28T18:00:49.986+0000] {taskinstance.py:341} INFO - ::group::Post task execution logs
[2025-03-28T18:00:49.987+0000] {standard_task_runner.py:124} ERROR - Failed to execute job 81 for task store_data (Constraint Error: PRIMARY KEY or UNIQUE constraint violation: duplicate key "632"; 1746)
Traceback (most recent call last):
  File "/home/airflow/.local/lib/python3.12/site-packages/airflow/task/task_runner/standard_task_runner.py", line 117, in _start_by_fork
    ret = args.func(args, dag=self.dag)
          ^^^^^^^^^^^^^^^^^^^^^^^^^^^^^
  File "/home/airflow/.local/lib/python3.12/site-packages/airflow/cli/cli_config.py", line 49, in command
    return func(*args, **kwargs)
           ^^^^^^^^^^^^^^^^^^^^^
  File "/home/airflow/.local/lib/python3.12/site-packages/airflow/utils/cli.py", line 116, in wrapper
    return f(*args, **kwargs)
           ^^^^^^^^^^^^^^^^^^
  File "/home/airflow/.local/lib/python3.12/site-packages/airflow/cli/commands/task_command.py", line 483, in task_run
    task_return_code = _run_task_by_selected_method(args, _dag, ti)
                       ^^^^^^^^^^^^^^^^^^^^^^^^^^^^^^^^^^^^^^^^^^^^
  File "/home/airflow/.local/lib/python3.12/site-packages/airflow/cli/commands/task_command.py", line 256, in _run_task_by_selected_method
    return _run_raw_task(args, ti)
           ^^^^^^^^^^^^^^^^^^^^^^^
  File "/home/airflow/.local/lib/python3.12/site-packages/airflow/cli/commands/task_command.py", line 341, in _run_raw_task
    return ti._run_raw_task(
           ^^^^^^^^^^^^^^^^^
  File "/home/airflow/.local/lib/python3.12/site-packages/airflow/utils/session.py", line 97, in wrapper
    return func(*args, session=session, **kwargs)
           ^^^^^^^^^^^^^^^^^^^^^^^^^^^^^^^^^^^^^^
  File "/home/airflow/.local/lib/python3.12/site-packages/airflow/models/taskinstance.py", line 3006, in _run_raw_task
    return _run_raw_task(
           ^^^^^^^^^^^^^^
  File "/home/airflow/.local/lib/python3.12/site-packages/airflow/models/taskinstance.py", line 274, in _run_raw_task
    TaskInstance._execute_task_with_callbacks(
  File "/home/airflow/.local/lib/python3.12/site-packages/airflow/models/taskinstance.py", line 3161, in _execute_task_with_callbacks
    result = self._execute_task(context, task_orig)
             ^^^^^^^^^^^^^^^^^^^^^^^^^^^^^^^^^^^^^^
  File "/home/airflow/.local/lib/python3.12/site-packages/airflow/models/taskinstance.py", line 3185, in _execute_task
    return _execute_task(self, context, task_orig)
           ^^^^^^^^^^^^^^^^^^^^^^^^^^^^^^^^^^^^^^^
  File "/home/airflow/.local/lib/python3.12/site-packages/airflow/models/taskinstance.py", line 768, in _execute_task
    result = _execute_callable(context=context, **execute_callable_kwargs)
             ^^^^^^^^^^^^^^^^^^^^^^^^^^^^^^^^^^^^^^^^^^^^^^^^^^^^^^^^^^^^^
  File "/home/airflow/.local/lib/python3.12/site-packages/airflow/models/taskinstance.py", line 734, in _execute_callable
    return ExecutionCallableRunner(
           ^^^^^^^^^^^^^^^^^^^^^^^^
  File "/home/airflow/.local/lib/python3.12/site-packages/airflow/utils/operator_helpers.py", line 252, in run
    return self.func(*args, **kwargs)
           ^^^^^^^^^^^^^^^^^^^^^^^^^^
  File "/home/airflow/.local/lib/python3.12/site-packages/airflow/models/baseoperator.py", line 424, in wrapper
    return func(self, *args, **kwargs)
           ^^^^^^^^^^^^^^^^^^^^^^^^^^^
  File "/home/airflow/.local/lib/python3.12/site-packages/airflow/operators/python.py", line 238, in execute
    return_value = self.execute_callable()
                   ^^^^^^^^^^^^^^^^^^^^^^^
  File "/home/airflow/.local/lib/python3.12/site-packages/airflow/operators/python.py", line 256, in execute_callable
    return runner.run(*self.op_args, **self.op_kwargs)
           ^^^^^^^^^^^^^^^^^^^^^^^^^^^^^^^^^^^^^^^^^^^
  File "/home/airflow/.local/lib/python3.12/site-packages/airflow/utils/operator_helpers.py", line 252, in run
    return self.func(*args, **kwargs)
           ^^^^^^^^^^^^^^^^^^^^^^^^^^
  File "/opt/airflow/dags/Gestioncommands.py", line 54, in store_data
    with duckdb.connect(DB_PATH) as conn:
         ^^^^^^^^^^^^^^^^^^^^^^^
  File "/opt/airflow/dags/Gestioncommands.py", line 111, in store_data
    conn.execute("INSERT INTO raw.clients SELECT * FROM clients_df")
duckdb.duckdb.ConstraintException: Constraint Error: PRIMARY KEY or UNIQUE constraint violation: duplicate key "632"
[2025-03-28T18:00:50.021+0000] {local_task_job_runner.py:266} INFO - Task exited with return code 1
[2025-03-28T18:00:50.049+0000] {taskinstance.py:3901} INFO - 0 downstream tasks scheduled from follow-on schedule check
[2025-03-28T18:00:50.054+0000] {local_task_job_runner.py:245} INFO - ::endgroup::
